[2021-12-11 15:27:40,527] {taskinstance.py:896} INFO - Dependencies all met for <TaskInstance: dag_postgres_create_table.create_dummy_table 2021-12-11T15:09:19.796352+00:00 [queued]>
[2021-12-11 15:27:40,543] {taskinstance.py:896} INFO - Dependencies all met for <TaskInstance: dag_postgres_create_table.create_dummy_table 2021-12-11T15:09:19.796352+00:00 [queued]>
[2021-12-11 15:27:40,545] {taskinstance.py:1087} INFO - 
--------------------------------------------------------------------------------
[2021-12-11 15:27:40,545] {taskinstance.py:1088} INFO - Starting attempt 3 of 3
[2021-12-11 15:27:40,546] {taskinstance.py:1089} INFO - 
--------------------------------------------------------------------------------
[2021-12-11 15:27:40,553] {taskinstance.py:1107} INFO - Executing <Task(PostgresOperator): create_dummy_table> on 2021-12-11T15:09:19.796352+00:00
[2021-12-11 15:27:40,557] {standard_task_runner.py:52} INFO - Started process 1534 to run task
[2021-12-11 15:27:40,561] {standard_task_runner.py:76} INFO - Running: ['***', 'tasks', 'run', 'dag_postgres_create_table', 'create_dummy_table', '2021-12-11T15:09:19.796352+00:00', '--job-id', '6', '--pool', 'default_pool', '--raw', '--subdir', 'DAGS_FOLDER/dag_postgres_create_table.py', '--cfg-path', '/tmp/tmpsjjgs8sj', '--error-file', '/tmp/tmp2mv1kczv']
[2021-12-11 15:27:40,563] {standard_task_runner.py:77} INFO - Job 6: Subtask create_dummy_table
[2021-12-11 15:27:40,609] {logging_mixin.py:104} INFO - Running <TaskInstance: dag_postgres_create_table.create_dummy_table 2021-12-11T15:09:19.796352+00:00 [running]> on host 3867aa8d4359
[2021-12-11 15:27:40,664] {taskinstance.py:1302} INFO - Exporting the following env vars:
AIRFLOW_CTX_DAG_OWNER=***
AIRFLOW_CTX_DAG_ID=dag_postgres_create_table
AIRFLOW_CTX_TASK_ID=create_dummy_table
AIRFLOW_CTX_EXECUTION_DATE=2021-12-11T15:09:19.796352+00:00
AIRFLOW_CTX_DAG_RUN_ID=manual__2021-12-11T15:09:19.796352+00:00
[2021-12-11 15:27:40,666] {postgres.py:68} INFO - Executing: CREATE TABLE scaled_data
    (
        idx_col integer,
        petal_width float,
        petal_length float
    );
    
[2021-12-11 15:27:40,677] {base.py:78} INFO - Using connection to: id: postgres_source. Host: postgres_source, Port: 5432, Schema: , Login: admin_user, Password: ***, extra: {}
[2021-12-11 15:27:40,685] {taskinstance.py:1501} ERROR - Task failed with exception
Traceback (most recent call last):
  File "/home/airflow/.local/lib/python3.6/site-packages/airflow/models/taskinstance.py", line 1157, in _run_raw_task
    self._prepare_and_execute_task_with_callbacks(context, task)
  File "/home/airflow/.local/lib/python3.6/site-packages/airflow/models/taskinstance.py", line 1331, in _prepare_and_execute_task_with_callbacks
    result = self._execute_task(context, task_copy)
  File "/home/airflow/.local/lib/python3.6/site-packages/airflow/models/taskinstance.py", line 1361, in _execute_task
    result = task_copy.execute(context=context)
  File "/home/airflow/.local/lib/python3.6/site-packages/airflow/providers/postgres/operators/postgres.py", line 70, in execute
    self.hook.run(self.sql, self.autocommit, parameters=self.parameters)
  File "/home/airflow/.local/lib/python3.6/site-packages/airflow/hooks/dbapi.py", line 177, in run
    with closing(self.get_conn()) as conn:
  File "/home/airflow/.local/lib/python3.6/site-packages/airflow/providers/postgres/hooks/postgres.py", line 115, in get_conn
    self.conn = psycopg2.connect(**conn_args)
  File "/home/airflow/.local/lib/python3.6/site-packages/psycopg2/__init__.py", line 122, in connect
    conn = _connect(dsn, connection_factory=connection_factory, **kwasync)
psycopg2.OperationalError: FATAL:  database "admin_user" does not exist

[2021-12-11 15:27:40,688] {taskinstance.py:1551} INFO - Marking task as FAILED. dag_id=dag_postgres_create_table, task_id=create_dummy_table, execution_date=20211211T150919, start_date=20211211T152740, end_date=20211211T152740
[2021-12-11 15:27:40,738] {local_task_job.py:149} INFO - Task exited with return code 1
