[2021-12-11 16:39:56,944] {taskinstance.py:896} INFO - Dependencies all met for <TaskInstance: dag_datalake_postgres.ingest_postgres_table 2021-12-11T16:39:08.021874+00:00 [queued]>
[2021-12-11 16:39:56,963] {taskinstance.py:896} INFO - Dependencies all met for <TaskInstance: dag_datalake_postgres.ingest_postgres_table 2021-12-11T16:39:08.021874+00:00 [queued]>
[2021-12-11 16:39:56,964] {taskinstance.py:1087} INFO - 
--------------------------------------------------------------------------------
[2021-12-11 16:39:56,965] {taskinstance.py:1088} INFO - Starting attempt 2 of 2
[2021-12-11 16:39:56,967] {taskinstance.py:1089} INFO - 
--------------------------------------------------------------------------------
[2021-12-11 16:39:56,976] {taskinstance.py:1107} INFO - Executing <Task(PythonOperator): ingest_postgres_table> on 2021-12-11T16:39:08.021874+00:00
[2021-12-11 16:39:56,980] {standard_task_runner.py:52} INFO - Started process 2716 to run task
[2021-12-11 16:39:56,986] {standard_task_runner.py:76} INFO - Running: ['***', 'tasks', 'run', 'dag_datalake_postgres', 'ingest_postgres_table', '2021-12-11T16:39:08.021874+00:00', '--job-id', '6', '--pool', 'default_pool', '--raw', '--subdir', 'DAGS_FOLDER/dag_datalake_postgres.py', '--cfg-path', '/tmp/tmp_vnnida1', '--error-file', '/tmp/tmpwcdve95t']
[2021-12-11 16:39:56,987] {standard_task_runner.py:77} INFO - Job 6: Subtask ingest_postgres_table
[2021-12-11 16:39:57,043] {logging_mixin.py:104} INFO - Running <TaskInstance: dag_datalake_postgres.ingest_postgres_table 2021-12-11T16:39:08.021874+00:00 [running]> on host a4b6b2594d54
[2021-12-11 16:39:57,088] {taskinstance.py:1302} INFO - Exporting the following env vars:
AIRFLOW_CTX_DAG_OWNER=***
AIRFLOW_CTX_DAG_ID=dag_datalake_postgres
AIRFLOW_CTX_TASK_ID=ingest_postgres_table
AIRFLOW_CTX_EXECUTION_DATE=2021-12-11T16:39:08.021874+00:00
AIRFLOW_CTX_DAG_RUN_ID=manual__2021-12-11T16:39:08.021874+00:00
[2021-12-11 16:39:57,090] {taskinstance.py:1501} ERROR - Task failed with exception
Traceback (most recent call last):
  File "/home/airflow/.local/lib/python3.6/site-packages/airflow/models/taskinstance.py", line 1157, in _run_raw_task
    self._prepare_and_execute_task_with_callbacks(context, task)
  File "/home/airflow/.local/lib/python3.6/site-packages/airflow/models/taskinstance.py", line 1331, in _prepare_and_execute_task_with_callbacks
    result = self._execute_task(context, task_copy)
  File "/home/airflow/.local/lib/python3.6/site-packages/airflow/models/taskinstance.py", line 1361, in _execute_task
    result = task_copy.execute(context=context)
  File "/home/airflow/.local/lib/python3.6/site-packages/airflow/operators/python.py", line 150, in execute
    return_value = self.execute_callable()
  File "/home/airflow/.local/lib/python3.6/site-packages/airflow/operators/python.py", line 161, in execute_callable
    return self.python_callable(*self.op_args, **self.op_kwargs)
  File "/opt/airflow/dags/scripts/postgres_ingestion.py", line 24, in ingest_postgres
    result_df = pd.read_sql(sql=query, engine = source_engine)
TypeError: read_sql() got an unexpected keyword argument 'engine'
[2021-12-11 16:39:57,093] {taskinstance.py:1551} INFO - Marking task as FAILED. dag_id=dag_datalake_postgres, task_id=ingest_postgres_table, execution_date=20211211T163908, start_date=20211211T163956, end_date=20211211T163957
[2021-12-11 16:39:57,117] {local_task_job.py:149} INFO - Task exited with return code 1
